[2025-04-06 07:59:03,404] {taskinstance.py:1179} INFO - Dependencies all met for <TaskInstance: Lead_scoring_inference_pipeline.encoding_categorical_variables manual__2025-04-06T07:59:00.264995+00:00 [queued]>
[2025-04-06 07:59:03,408] {taskinstance.py:1179} INFO - Dependencies all met for <TaskInstance: Lead_scoring_inference_pipeline.encoding_categorical_variables manual__2025-04-06T07:59:00.264995+00:00 [queued]>
[2025-04-06 07:59:03,408] {taskinstance.py:1376} INFO - 
--------------------------------------------------------------------------------
[2025-04-06 07:59:03,408] {taskinstance.py:1377} INFO - Starting attempt 1 of 2
[2025-04-06 07:59:03,408] {taskinstance.py:1378} INFO - 
--------------------------------------------------------------------------------
[2025-04-06 07:59:03,427] {taskinstance.py:1397} INFO - Executing <Task(PythonOperator): encoding_categorical_variables> on 2025-04-06 07:59:00.264995+00:00
[2025-04-06 07:59:03,433] {standard_task_runner.py:52} INFO - Started process 14412 to run task
[2025-04-06 07:59:03,435] {standard_task_runner.py:79} INFO - Running: ['airflow', 'tasks', 'run', 'Lead_scoring_inference_pipeline', 'encoding_categorical_variables', 'manual__2025-04-06T07:59:00.264995+00:00', '--job-id', '44', '--raw', '--subdir', 'DAGS_FOLDER/Lead_scoring_inference_pipeline/.ipynb_checkpoints/lead_scoring_inference_pipeline-checkpoint.py', '--cfg-path', '/tmp/tmpwdy2qn1z', '--error-file', '/tmp/tmp6_a6evuy']
[2025-04-06 07:59:03,436] {standard_task_runner.py:80} INFO - Job 44: Subtask encoding_categorical_variables
[2025-04-06 07:59:03,474] {task_command.py:371} INFO - Running <TaskInstance: Lead_scoring_inference_pipeline.encoding_categorical_variables manual__2025-04-06T07:59:00.264995+00:00 [running]> on host c6537eab7989
[2025-04-06 07:59:03,627] {taskinstance.py:1589} INFO - Exporting the following env vars:
AIRFLOW_CTX_DAG_OWNER=airflow
AIRFLOW_CTX_DAG_ID=Lead_scoring_inference_pipeline
AIRFLOW_CTX_TASK_ID=encoding_categorical_variables
AIRFLOW_CTX_EXECUTION_DATE=2025-04-06T07:59:00.264995+00:00
AIRFLOW_CTX_TRY_NUMBER=1
AIRFLOW_CTX_DAG_RUN_ID=manual__2025-04-06T07:59:00.264995+00:00
[2025-04-06 07:59:03,628] {taskinstance.py:1909} ERROR - Task failed with exception
Traceback (most recent call last):
  File "/opt/conda/lib/python3.8/site-packages/airflow/operators/python.py", line 171, in execute
    return_value = self.execute_callable()
  File "/opt/conda/lib/python3.8/site-packages/airflow/operators/python.py", line 189, in execute_callable
    return self.python_callable(*self.op_args, **self.op_kwargs)
  File "/home/mlopsAssignment/Airflow/Dags/Lead_scoring_inference_pipeline/utils.py", line 49, in encode_features
    conn = sqlite3.connect(DB_PATH+DB_FILE_NAME)
sqlite3.OperationalError: unable to open database file
[2025-04-06 07:59:03,630] {taskinstance.py:1415} INFO - Marking task as UP_FOR_RETRY. dag_id=Lead_scoring_inference_pipeline, task_id=encoding_categorical_variables, execution_date=20250406T075900, start_date=20250406T075903, end_date=20250406T075903
[2025-04-06 07:59:03,649] {standard_task_runner.py:92} ERROR - Failed to execute job 44 for task encoding_categorical_variables (unable to open database file; 14412)
[2025-04-06 07:59:03,688] {local_task_job.py:156} INFO - Task exited with return code 1
[2025-04-06 07:59:03,745] {local_task_job.py:273} INFO - 0 downstream tasks scheduled from follow-on schedule check
